<?xml version="1.0"?>
<robot name="fr3">
  <link name="fr3_link0"/>
  <joint name="fr3_joint1" type="revolute">
    <parent link="fr3_link0"/>
    <child link="fr3_link1"/>
    <origin xyz="0 0 0.333" rpy="0 0 0"/>
    <axis xyz="0 0 1"/>
    <limit lower="-2.8973" upper="2.8973"/>
  </joint>
  <link name="fr3_link1"/>
  <joint name="fr3_joint2" type="revolute">
    <parent link="fr3_link1"/>
    <child link="fr3_link2"/>
    <origin xyz="0 0 0" rpy="-1.57079632679 0 0"/>
    <axis xyz="0 0 1"/>
    <limit lower="-1.7628" upper="1.7628"/>
  </joint>
  <link name="fr3_link2"/>
  <joint name="fr3_joint3" type="revolute">
    <parent link="fr3_link2"/>
    <child link="fr3_link3"/>
    <origin xyz="0 -0.316 0" rpy="1.57079632679 0 0"/>
    <axis xyz="0 0 1"/>
    <limit lower="-2.8973" upper="2.8973"/>
  </joint>
  <link name="fr3_link3"/>
  <joint name="fr3_joint4" type="revolute">
    <parent link="fr3_link3"/>
    <child link="fr3_link4"/>
    <origin xyz="0.0825 0 0" rpy="1.57079632679 0 0"/>
    <axis xyz="0 0 1"/>
    <limit lower="-3.0718" upper="-0.0698"/>
  </joint>
  <link name="fr3_link4"/>
  <joint name="fr3_joint5" type="revolute">
    <parent link="fr3_link4"/>
    <child link="fr3_link5"/>
    <origin xyz="-0.0825 0.384 0" rpy="-1.57079632679 0 0"/>
    <axis xyz="0 0 1"/>
    <limit lower="-2.8973" upper="2.8973"/>
  </joint>
  <link name="fr3_link5"/>
  <joint name="fr3_joint6" type="revolute">
    <parent link="fr3_link5"/>
    <child link="fr3_link6"/>
    <origin xyz="0 0 0" rpy="1.57079632679 0 0"/>
    <axis xyz="0 0 1"/>
    <limit lower="-0.0175" upper="3.7525"/>
  </joint>
  <link name="fr3_link6"/>
  <joint name="fr3_joint7" type="revolute">
    <parent link="fr3_link6"/>
    <child link="fr3_link7"/>
    <origin xyz="0.088 0 0" rpy="1.57079632679 0 0"/>
    <axis xyz="0 0 1"/>
    <limit lower="-2.8973" upper="2.8973"/>
  </joint>
  <link name="fr3_link7"/>

  <joint name="fr3_hand_joint" type="fixed">
    <parent link="fr3_link7"/>
    <child link="fr3_hand"/>
    <origin xyz="0 0 0.107" rpy="0 0 0"/>
  </joint>
  <link name="fr3_hand"/>

  <joint name="fr3_finger_joint1" type="prismatic">
    <parent link="fr3_hand"/>
    <child link="fr3_leftfinger"/>
    <origin xyz="0 0 0.0584" rpy="0 0 0"/>
    <axis xyz="0 1 0"/>
    <limit lower="0.0" upper="0.04"/>
  </joint>
  <link name="fr3_leftfinger"/>

  <joint name="fr3_finger_joint2" type="prismatic">
    <parent link="fr3_hand"/>
    <child link="fr3_rightfinger"/>
    <origin xyz="0 0 0.0584" rpy="0 0 0"/>
    <axis xyz="0 -1 0"/>
    <limit lower="0.0" upper="0.04"/>
  </joint>
  <link name="fr3_rightfinger"/>

  <joint name="fr3_hand_tcp_joint" type="fixed">
    <parent link="fr3_hand"/>
    <child link="fr3_hand_tcp"/>
    <origin xyz="0 0 0.12" rpy="0 0 0"/>
  </joint>
  <link name="fr3_hand_tcp"/>
</robot>
