<?xml version="1.0" encoding="utf-8"?>
<!-- This URDF was automatically created by SolidWorks to URDF Exporter! Originally created by Stephen Brawner (brawner@gmail.com) 
     Commit Version: 1.6.0-4-g7f85cfe  Build Version: 1.6.7995.38578
     For more information, please see http://wiki.ros.org/sw_urdf_exporter -->
<robot
  name="brainco-righthand-URDF-V2">
  <link
    name="base_link">
    <inertial>
      <origin
        xyz="-0.00477210166218609 -0.00143682517693859 0.050518681369968"
        rpy="0 0 0" />
      <mass
        value="0.0306701603277963" />
      <inertia
        ixx="2.22653142417882E-05"
        ixy="2.619146157182E-07"
        ixz="1.8532221192488E-07"
        iyy="1.55386679883247E-05"
        iyz="-1.26178696418883E-06"
        izz="8.58493926893206E-06" />
    </inertial>
    <visual>
      <origin
        xyz="0 0 0"
        rpy="0 0 0" />
      <geometry>
        <mesh
          filename="package://brainco-righthand-URDF-V2/meshes/base_link.STL" />
      </geometry>
      <material
        name="">
        <color
          rgba="1 1 1 1" />
      </material>
    </visual>
    <collision>
      <origin
        xyz="0 0 0"
        rpy="0 0 0" />
      <geometry>
        <mesh
          filename="package://brainco-righthand-URDF-V2/meshes/base_link.STL" />
      </geometry>
    </collision>
  </link>
  <link
    name="thumb_metacarpal_link">
    <inertial>
      <origin
        xyz="1.51105893291988E-05 0.00707242532016975 -0.00420847293427094"
        rpy="0 0 0" />
      <mass
        value="0.00116019531148996" />
      <inertia
        ixx="1.59239837111329E-07"
        ixy="-4.69100836631313E-09"
        ixz="4.92933775261587E-10"
        iyy="1.60913456568321E-07"
        iyz="-1.48146725871811E-08"
        izz="5.13550255314669E-08" />
    </inertial>
    <visual>
      <origin
        xyz="0 0 0"
        rpy="0 0 0" />
      <geometry>
        <mesh
          filename="package://brainco-righthand-URDF-V2/meshes/thumb_metacarpal_link.STL" />
      </geometry>
      <material
        name="">
        <color
          rgba="1 1 1 1" />
      </material>
    </visual>
    <collision>
      <origin
        xyz="0 0 0"
        rpy="0 0 0" />
      <geometry>
        <mesh
          filename="package://brainco-righthand-URDF-V2/meshes/thumb_metacarpal_link.STL" />
      </geometry>
    </collision>
  </link>
  <joint
    name="thumb_metacarpal_joint"
    type="revolute">
    <origin
      xyz="0.005619 0.019867 0.027825"
      rpy="0 0 -0.16787" />
    <parent
      link="base_link" />
    <child
      link="thumb_metacarpal_link" />
    <axis
      xyz="0 0 1" />
    <limit
      lower="-1.5184"
      upper="0"
      effort="0.5"
      velocity="2.6175" />
  </joint>
  <link
    name="thumb_proximal_link">
    <inertial>
      <origin
        xyz="-4.57172872239675E-07 0.0250090110844873 -0.00175049403575901"
        rpy="0 0 0" />
      <mass
        value="0.013437308865305" />
      <inertia
        ixx="3.23319869389856E-06"
        ixy="-1.19075992087717E-10"
        ixz="1.24443381455412E-11"
        iyy="5.64506002356025E-07"
        iyz="5.04129419740444E-08"
        izz="3.39928434904953E-06" />
    </inertial>
    <visual>
      <origin
        xyz="0 0 0"
        rpy="0 0 0" />
      <geometry>
        <mesh
          filename="package://brainco-righthand-URDF-V2/meshes/thumb_proximal_link.STL" />
      </geometry>
      <material
        name="">
        <color
          rgba="1 1 1 1" />
      </material>
    </visual>
    <collision>
      <origin
        xyz="0 0 0"
        rpy="0 0 0" />
      <geometry>
        <mesh
          filename="package://brainco-righthand-URDF-V2/meshes/thumb_proximal_link.STL" />
      </geometry>
    </collision>
  </link>
  <joint
    name="thumb_proximal_joint"
    type="revolute">
    <origin
      xyz="0 0.014227 0"
      rpy="0.17488 0.23736 0.16787" />
    <parent
      link="thumb_metacarpal_link" />
    <child
      link="thumb_proximal_link" />
    <axis
      xyz="1 0 0" />
    <limit
      lower="0"
      upper="1.0472"
      effort="1.1"
      velocity="2.5303" />
  </joint>
  <link
    name="thumb_distal_link">
    <inertial>
      <origin
        xyz="-5.88258313588552E-09 0.0117544716247142 1.13324397438969E-05"
        rpy="0 0 0" />
      <mass
        value="0.00417181579838271" />
      <inertia
        ixx="1.67793545309794E-07"
        ixy="7.15927847824152E-12"
        ixz="-6.80095370888918E-12"
        iyy="1.15362128819331E-07"
        iyz="1.2517499089377E-08"
        izz="2.19553178338424E-07" />
    </inertial>
    <visual>
      <origin
        xyz="0 0 0"
        rpy="0 0 0" />
      <geometry>
        <mesh
          filename="package://brainco-righthand-URDF-V2/meshes/thumb_distal_link.STL" />
      </geometry>
      <material
        name="">
        <color
          rgba="1 1 1 1" />
      </material>
    </visual>
    <collision>
      <origin
        xyz="0 0 0"
        rpy="0 0 0" />
      <geometry>
        <mesh
          filename="package://brainco-righthand-URDF-V2/meshes/thumb_distal_link.STL" />
      </geometry>
    </collision>
  </link>
  <joint
    name="thumb_distal_joint"
    type="revolute">
    <origin
      xyz="0 0.052 0"
      rpy="0 0 0" />
    <parent
      link="thumb_proximal_link" />
    <child
      link="thumb_distal_link" />
    <axis
      xyz="1 0 0" />
    <limit
      lower="0"
      upper="1.0472"
      effort="1.1"
      velocity="2.5303" />
  </joint>
  <link
    name="thumb_tip">
    <inertial>
      <origin
        xyz="0 -8.79922039356273E-05 -1.73472347597681E-18"
        rpy="0 0 0" />
      <mass
        value="6.54498469497874E-08" />
      <inertia
        ixx="1.63624617374468E-15"
        ixy="-6.16297582203915E-33"
        ixz="-4.93038065763132E-32"
        iyy="1.63624617374468E-15"
        iyz="1.00148357108136E-32"
        izz="1.63624617374469E-15" />
    </inertial>
    <visual>
      <origin
        xyz="0 0 0"
        rpy="0 0 0" />
      <geometry>
        <mesh
          filename="package://brainco-righthand-URDF-V2/meshes/thumb_tip.STL" />
      </geometry>
      <material
        name="">
        <color
          rgba="1 1 1 1" />
      </material>
    </visual>
    <collision>
      <origin
        xyz="0 0 0"
        rpy="0 0 0" />
      <geometry>
        <mesh
          filename="package://brainco-righthand-URDF-V2/meshes/thumb_tip.STL" />
      </geometry>
    </collision>
  </link>
  <joint
    name="thumb_tip"
    type="revolute">
    <origin
      xyz="0 0.026529 -0.0017734"
      rpy="-0.06675 0 0" />
    <parent
      link="thumb_distal_link" />
    <child
      link="thumb_tip" />
    <axis
      xyz="1 0 0" />
    <limit
      lower="0"
      upper="0"
      effort="0"
      velocity="0" />
  </joint>
  <link
    name="index_proximal_link">
    <inertial>
      <origin
        xyz="-0.00223495193290077 3.15874279788186E-06 0.0176402020319161"
        rpy="0 0 0" />
      <mass
        value="0.00195502251331252" />
      <inertia
        ixx="2.51945688432676E-07"
        ixy="1.19772642527626E-11"
        ixz="-6.37275646674549E-09"
        iyy="2.36435336197133E-07"
        iyz="1.65019098402875E-10"
        izz="9.30351046795666E-08" />
    </inertial>
    <visual>
      <origin
        xyz="0 0 0"
        rpy="0 0 0" />
      <geometry>
        <mesh
          filename="package://brainco-righthand-URDF-V2/meshes/index_proximal_link.STL" />
      </geometry>
      <material
        name="">
        <color
          rgba="1 1 1 1" />
      </material>
    </visual>
    <collision>
      <origin
        xyz="0 0 0"
        rpy="0 0 0" />
      <geometry>
        <mesh
          filename="package://brainco-righthand-URDF-V2/meshes/index_proximal_link.STL" />
      </geometry>
    </collision>
  </link>
  <joint
    name="index_proximal_joint"
    type="revolute">
    <origin
      xyz="-0.0021181 0.029568 0.080876"
      rpy="-0.11819 0.14743 -0.17422" />
    <parent
      link="base_link" />
    <child
      link="index_proximal_link" />
    <axis
      xyz="0 1 0" />
    <limit
      lower="0"
      upper="1.4661"
      effort="2"
      velocity="2.2685" />
  </joint>
  <link
    name="index_distal_link">
    <inertial>
      <origin
        xyz="0.00418341335261295 1.16596677458836E-07 0.015364336404132"
        rpy="0 0 0" />
      <mass
        value="0.00406296182843578" />
      <inertia
        ixx="3.65279307173044E-07"
        ixy="-2.87250721751561E-12"
        ixz="-1.02338195662283E-07"
        iyy="3.96973276545597E-07"
        iyz="-3.6418238169009E-12"
        izz="1.04994676979538E-07" />
    </inertial>
    <visual>
      <origin
        xyz="0 0 0"
        rpy="0 0 0" />
      <geometry>
        <mesh
          filename="package://brainco-righthand-URDF-V2/meshes/index_distal_link.STL" />
      </geometry>
      <material
        name="">
        <color
          rgba="1 1 1 1" />
      </material>
    </visual>
    <collision>
      <origin
        xyz="0 0 0"
        rpy="0 0 0" />
      <geometry>
        <mesh
          filename="package://brainco-righthand-URDF-V2/meshes/index_distal_link.STL" />
      </geometry>
    </collision>
  </link>
  <joint
    name="index_distal_joint"
    type="revolute">
    <origin
      xyz="0 0 0.032"
      rpy="0 0 0" />
    <parent
      link="index_proximal_link" />
    <child
      link="index_distal_link" />
    <axis
      xyz="0 1 0" />
    <limit
      lower="0"
      upper="1.693"
      effort="2"
      velocity="2.2685" />
  </joint>
  <link
    name="index_tip">
    <inertial>
      <origin
        xyz="0 6.93889390390723E-18 2.77555756156289E-17"
        rpy="0 0 0" />
      <mass
        value="6.54498469497874E-08" />
      <inertia
        ixx="1.63624617374468E-15"
        ixy="-4.93038065763132E-32"
        ixz="0"
        iyy="1.63624617374468E-15"
        iyz="-1.23259516440783E-32"
        izz="1.63624617374468E-15" />
    </inertial>
    <visual>
      <origin
        xyz="0 0 0"
        rpy="0 0 0" />
      <geometry>
        <mesh
          filename="package://brainco-righthand-URDF-V2/meshes/index_tip.STL" />
      </geometry>
      <material
        name="">
        <color
          rgba="1 1 1 1" />
      </material>
    </visual>
    <collision>
      <origin
        xyz="0 0 0"
        rpy="0 0 0" />
      <geometry>
        <mesh
          filename="package://brainco-righthand-URDF-V2/meshes/index_tip.STL" />
      </geometry>
    </collision>
  </link>
  <joint
    name="index_tip_joint"
    type="revolute">
    <origin
      xyz="0.011097 0 0.035739"
      rpy="0 0.4756 0" />
    <parent
      link="index_distal_link" />
    <child
      link="index_tip" />
    <axis
      xyz="0 1 0" />
    <limit
      lower="0"
      upper="0"
      effort="0"
      velocity="0" />
  </joint>
  <link
    name="middle_proximal_link">
    <inertial>
      <origin
        xyz="-0.00222511101223748 5.25632286621502E-06 0.0203007776295122"
        rpy="0 0 0" />
      <mass
        value="0.00232228766449838" />
      <inertia
        ixx="3.66996237195385E-07"
        ixy="2.68340899394266E-11"
        ixz="-9.79836587937118E-09"
        iyy="3.52645347928617E-07"
        iyz="2.57865582739015E-10"
        izz="1.12233932527467E-07" />
    </inertial>
    <visual>
      <origin
        xyz="0 0 0"
        rpy="0 0 0" />
      <geometry>
        <mesh
          filename="package://brainco-righthand-URDF-V2/meshes/middle_proximal_link.STL" />
      </geometry>
      <material
        name="">
        <color
          rgba="1 1 1 1" />
      </material>
    </visual>
    <collision>
      <origin
        xyz="0 0 0"
        rpy="0 0 0" />
      <geometry>
        <mesh
          filename="package://brainco-righthand-URDF-V2/meshes/middle_proximal_link.STL" />
      </geometry>
    </collision>
  </link>
  <joint
    name="middle_proximal_joint"
    type="revolute">
    <origin
      xyz="-0.0045767 0.010051 0.084993"
      rpy="-0.039468 0.1483 -0.057975" />
    <parent
      link="base_link" />
    <child
      link="middle_proximal_link" />
    <axis
      xyz="0 1 0" />
    <limit
      lower="0"
      upper="1.4661"
      effort="2"
      velocity="2.2685" />
  </joint>
  <link
    name="middle_distal_link">
    <inertial>
      <origin
        xyz="0.0049863469326964 3.20968126441695E-07 0.0178210318376746"
        rpy="0 0 0" />
      <mass
        value="0.00491866388593896" />
      <inertia
        ixx="5.54531291618193E-07"
        ixy="-3.82751343578468E-12"
        ixz="-1.61139292206417E-07"
        iyy="6.07133263023386E-07"
        iyz="-1.20501452509702E-11"
        izz="1.45091109192225E-07" />
    </inertial>
    <visual>
      <origin
        xyz="0 0 0"
        rpy="0 0 0" />
      <geometry>
        <mesh
          filename="package://brainco-righthand-URDF-V2/meshes/middle_distal_link.STL" />
      </geometry>
      <material
        name="">
        <color
          rgba="1 1 1 1" />
      </material>
    </visual>
    <collision>
      <origin
        xyz="0 0 0"
        rpy="0 0 0" />
      <geometry>
        <mesh
          filename="package://brainco-righthand-URDF-V2/meshes/middle_distal_link.STL" />
      </geometry>
    </collision>
  </link>
  <joint
    name="middle_distal_joint"
    type="revolute">
    <origin
      xyz="0 0 0.037"
      rpy="0 0 0" />
    <parent
      link="middle_proximal_link" />
    <child
      link="middle_distal_link" />
    <axis
      xyz="0 1 0" />
    <limit
      lower="0"
      upper="1.693"
      effort="2"
      velocity="2.2685" />
  </joint>
  <link
    name="middle_tip">
    <inertial>
      <origin
        xyz="0 -3.46944695195361E-18 0"
        rpy="0 0 0" />
      <mass
        value="6.54498469497874E-08" />
      <inertia
        ixx="1.63624617374468E-15"
        ixy="-6.16297582203915E-33"
        ixz="9.86076131526265E-32"
        iyy="1.63624617374468E-15"
        iyz="3.08148791101958E-33"
        izz="1.63624617374468E-15" />
    </inertial>
    <visual>
      <origin
        xyz="0 0 0"
        rpy="0 0 0" />
      <geometry>
        <mesh
          filename="package://brainco-righthand-URDF-V2/meshes/middle_tip.STL" />
      </geometry>
      <material
        name="">
        <color
          rgba="1 1 1 1" />
      </material>
    </visual>
    <collision>
      <origin
        xyz="0 0 0"
        rpy="0 0 0" />
      <geometry>
        <mesh
          filename="package://brainco-righthand-URDF-V2/meshes/middle_tip.STL" />
      </geometry>
    </collision>
  </link>
  <joint
    name="middle_tip_joint"
    type="revolute">
    <origin
      xyz="0.0125575670114349 0 0.0404419749600572"
      rpy="0 0.475602221168456 0" />
    <parent
      link="middle_distal_link" />
    <child
      link="middle_tip" />
    <axis
      xyz="0 -1 0" />
    <limit
      lower="0"
      upper="0"
      effort="0"
      velocity="0" />
  </joint>
  <link
    name="ring_proximal_link">
    <inertial>
      <origin
        xyz="-0.00234494526421466 5.8795475560789E-06 0.0191774025495976"
        rpy="0 0 0" />
      <mass
        value="0.00214992998311425" />
      <inertia
        ixx="3.14177684848331E-07"
        ixy="3.3438233110566E-11"
        ixz="-7.7898178089235E-09"
        iyy="2.97613170150892E-07"
        iyz="2.41251871798122E-10"
        izz="1.02115432336749E-07" />
    </inertial>
    <visual>
      <origin
        xyz="0 0 0"
        rpy="0 0 0" />
      <geometry>
        <mesh
          filename="package://brainco-righthand-URDF-V2/meshes/ring_proximal_link.STL" />
      </geometry>
      <material
        name="">
        <color
          rgba="1 1 1 1" />
      </material>
    </visual>
    <collision>
      <origin
        xyz="0 0 0"
        rpy="0 0 0" />
      <geometry>
        <mesh
          filename="package://brainco-righthand-URDF-V2/meshes/ring_proximal_link.STL" />
      </geometry>
    </collision>
  </link>
  <joint
    name="ring_proximal_joint"
    type="revolute">
    <origin
      xyz="-0.0046709 -0.010037 0.083982"
      rpy="0.039462 0.14721 0.057932" />
    <parent
      link="base_link" />
    <child
      link="ring_proximal_link" />
    <axis
      xyz="0 1 0" />
    <limit
      lower="0"
      upper="1.4661"
      effort="2"
      velocity="2.2685" />
  </joint>
  <link
    name="ring_distal_link">
    <inertial>
      <origin
        xyz="0.00471282047041737 -2.42853075739513E-08 0.0172486573668856"
        rpy="0 0 0" />
      <mass
        value="0.00466283373690043" />
      <inertia
        ixx="5.09075629611805E-07"
        ixy="-3.12030946891553E-12"
        ixz="-1.48822357561025E-07"
        iyy="5.56818055205826E-07"
        iyz="-3.81917701976479E-12"
        izz="1.34389193498435E-07" />
    </inertial>
    <visual>
      <origin
        xyz="0 0 0"
        rpy="0 0 0" />
      <geometry>
        <mesh
          filename="package://brainco-righthand-URDF-V2/meshes/ring_distal_link.STL" />
      </geometry>
      <material
        name="">
        <color
          rgba="1 1 1 1" />
      </material>
    </visual>
    <collision>
      <origin
        xyz="0 0 0"
        rpy="0 0 0" />
      <geometry>
        <mesh
          filename="package://brainco-righthand-URDF-V2/meshes/ring_distal_link.STL" />
      </geometry>
    </collision>
  </link>
  <joint
    name="ring_distal_joint"
    type="revolute">
    <origin
      xyz="0 0 0.035"
      rpy="0 0 0" />
    <parent
      link="ring_proximal_link" />
    <child
      link="ring_distal_link" />
    <axis
      xyz="0 1 0" />
    <limit
      lower="0"
      upper="1.693"
      effort="2"
      velocity="2.2685" />
  </joint>
  <link
    name="ring_tip">
    <inertial>
      <origin
        xyz="0 0 0"
        rpy="0 0 0" />
      <mass
        value="6.54498469497874E-08" />
      <inertia
        ixx="1.63624617374468E-15"
        ixy="-6.16297582203915E-33"
        ixz="9.86076131526265E-32"
        iyy="1.63624617374468E-15"
        iyz="0"
        izz="1.63624617374468E-15" />
    </inertial>
    <visual>
      <origin
        xyz="0 0 0"
        rpy="0 0 0" />
      <geometry>
        <mesh
          filename="package://brainco-righthand-URDF-V2/meshes/ring_tip.STL" />
      </geometry>
      <material
        name="">
        <color
          rgba="1 1 1 1" />
      </material>
    </visual>
    <collision>
      <origin
        xyz="0 0 0"
        rpy="0 0 0" />
      <geometry>
        <mesh
          filename="package://brainco-righthand-URDF-V2/meshes/ring_tip.STL" />
      </geometry>
    </collision>
  </link>
  <joint
    name="ring_tip_joint"
    type="revolute">
    <origin
      xyz="0.012266 0 0.039501"
      rpy="0 0.4756 0" />
    <parent
      link="ring_distal_link" />
    <child
      link="ring_tip" />
    <axis
      xyz="0 1 0" />
    <limit
      lower="0"
      upper="0"
      effort="0"
      velocity="0" />
  </joint>
  <link
    name="pinky_proximal_link">
    <inertial>
      <origin
        xyz="-0.00213212021184184 7.75039446080511E-06 0.0160671583560377"
        rpy="0 0 0" />
      <mass
        value="0.00173854673404671" />
      <inertia
        ixx="1.975632135501E-07"
        ixy="2.23402433053397E-11"
        ixz="-4.58425663692231E-09"
        iyy="1.8202304308332E-07"
        iyz="1.08028441148425E-10"
        izz="8.21624712033188E-08" />
    </inertial>
    <visual>
      <origin
        xyz="0 0 0"
        rpy="0 0 0" />
      <geometry>
        <mesh
          filename="package://brainco-righthand-URDF-V2/meshes/pinky_proximal_link.STL" />
      </geometry>
      <material
        name="">
        <color
          rgba="1 1 1 1" />
      </material>
    </visual>
    <collision>
      <origin
        xyz="0 0 0"
        rpy="0 0 0" />
      <geometry>
        <mesh
          filename="package://brainco-righthand-URDF-V2/meshes/pinky_proximal_link.STL" />
      </geometry>
    </collision>
  </link>
  <joint
    name="pinky_proximal_joint"
    type="revolute">
    <origin
      xyz="-0.0023566 -0.029366 0.078694"
      rpy="0.11815 0.14491 0.17392" />
    <parent
      link="base_link" />
    <child
      link="pinky_proximal_link" />
    <axis
      xyz="0 1 0" />
    <limit
      lower="0"
      upper="1.466076572"
      effort="2"
      velocity="2.2685" />
  </joint>
  <link
    name="pinky_distal_link">
    <inertial>
      <origin
        xyz="0.00398575710171677 -1.18612275255142E-07 0.014107352014143"
        rpy="0 0 0" />
      <mass
        value="0.00375757190949148" />
      <inertia
        ixx="2.8828728315904E-07"
        ixy="8.06578660095813E-13"
        ixz="-7.78224737732238E-08"
        iyy="3.10873475225446E-07"
        iyz="3.24944213201207E-12"
        izz="9.12935515594715E-08" />
    </inertial>
    <visual>
      <origin
        xyz="0 0 0"
        rpy="0 0 0" />
      <geometry>
        <mesh
          filename="package://brainco-righthand-URDF-V2/meshes/pinky_distal_link.STL" />
      </geometry>
      <material
        name="">
        <color
          rgba="1 1 1 1" />
      </material>
    </visual>
    <collision>
      <origin
        xyz="0 0 0"
        rpy="0 0 0" />
      <geometry>
        <mesh
          filename="package://brainco-righthand-URDF-V2/meshes/pinky_distal_link.STL" />
      </geometry>
    </collision>
  </link>
  <joint
    name="pinky_distal_joint"
    type="revolute">
    <origin
      xyz="0 0 0.029"
      rpy="0 0 0" />
    <parent
      link="pinky_proximal_link" />
    <child
      link="pinky_distal_link" />
    <axis
      xyz="0 1 0" />
    <limit
      lower="0"
      upper="1.693"
      effort="2"
      velocity="2.2685" />
  </joint>
  <link
    name="pinky_tip">
    <inertial>
      <origin
        xyz="3.46944695195361E-18 -5.20417042793042E-18 0"
        rpy="0 0 0" />
      <mass
        value="6.54498469497874E-08" />
      <inertia
        ixx="1.63624617374468E-15"
        ixy="0"
        ixz="0"
        iyy="1.63624617374468E-15"
        iyz="4.93038065763132E-32"
        izz="1.63624617374468E-15" />
    </inertial>
    <visual>
      <origin
        xyz="0 0 0"
        rpy="0 0 0" />
      <geometry>
        <mesh
          filename="package://brainco-righthand-URDF-V2/meshes/pinky_tip.STL" />
      </geometry>
      <material
        name="">
        <color
          rgba="1 1 1 1" />
      </material>
    </visual>
    <collision>
      <origin
        xyz="0 0 0"
        rpy="0 0 0" />
      <geometry>
        <mesh
          filename="package://brainco-righthand-URDF-V2/meshes/pinky_tip.STL" />
      </geometry>
    </collision>
  </link>
  <joint
    name="pinky_tip_joint"
    type="revolute">
    <origin
      xyz="0.010221 0 0.032918"
      rpy="0 0.4756 0" />
    <parent
      link="pinky_distal_link" />
    <child
      link="pinky_tip" />
    <axis
      xyz="0 1 0" />
    <limit
      lower="0"
      upper="0"
      effort="0"
      velocity="0" />
  </joint>
</robot>