<?xml version="1.0" ?>
<!-- =================================================================================== -->
<!-- |    This document was autogenerated by xacro from ./src/moderos_descriptions/TR4_description/xacro/TR4.xacro | -->
<!-- |    EDITING THIS FILE BY HAND IS NOT RECOMMENDED                                 | -->
<!-- =================================================================================== -->
<robot name="TR4">
  <material name="tr4_dark_grey">
    <color rgba="0.20 0.20 0.22 1.0"/>
  </material>
  <material name="tr4_mid_grey">
    <color rgba="0.40 0.40 0.42 1.0"/>
  </material>
  <material name="tr4_light_grey">
    <color rgba="0.80 0.80 0.82 1.0"/>
  </material>
  <material name="tr4_black_metal">
    <color rgba="0.10 0.10 0.11 1.0"/>
  </material>
  <!-- base_link -->
  <link name="base_link">
    <inertial>
      <origin xyz="-0.044044 4.1046E-05 0.35314" rpy="0 0 0"/>
      <mass value="62.34"/>
      <inertia ixx="2.4972" ixy="-5.136E-05" ixz="-0.026499" iyy="2.9084" iyz="-0.00014713" izz="1.479"/>
    </inertial>
    <visual>
      <origin xyz="0 0 0" rpy="0 0 0"/>
      <geometry>
        <mesh filename="moderos_descriptions/TR4_description_v2/meshes/base_link.STL"/>
      </geometry>
      <material name="tr4_dark_grey"/>
    </visual>
    <collision>
      <origin xyz="0 0 0" rpy="0 0 0"/>
      <geometry>
        <mesh filename="moderos_descriptions/TR4_description_v2/meshes/base_link.STL"/>
      </geometry>
    </collision>
  </link>

  <link name="torso">
    <inertial>
      <origin xyz="0.00027401 -0.14991 0.91143" rpy="0 0 0"/>
      <mass value="3.3193"/>
      <inertia ixx="0.016893" ixy="-1.2784E-05" ixz="-7.5907E-05" iyy="0.026595" iyz="-0.0010839" izz="0.018448"/>
    </inertial>
    <visual>
      <origin xyz="0 0 0" rpy="0 0 0"/>
      <geometry>
        <mesh filename="moderos_descriptions/TR4_description_v2/meshes/torso.STL"/>
      </geometry>
      <material name="tr4_mid_grey"/>
    </visual>
    <collision>
      <origin xyz="0 0 0" rpy="0 0 0"/>
      <geometry>
        <mesh filename="moderos_descriptions/TR4_description_v2/meshes/torso.STL"/>
      </geometry>
    </collision>
  </link>

  <!-- elevation joint -->
  <!-- elevation joint -->
  <joint name="elevation" type="prismatic">
    <origin rpy="0 0 1.5708" xyz="-0.11205 -0.00063586 0.39566"/>
    <parent link="base_link"/>
    <child link="torso"/>
    <axis xyz="0 0 1"/>
  <!-- Hardware spec: starts at top (0), moves downward to -0.8 m -->
  <limit effort="1000" lower="-0.8" upper="0.0" velocity="0.8"/>
  </joint>
  <!-- Base Link -->
  <link name="left_arm_base_link">
    <inertial>
      <origin rpy="0 0 0" xyz="-0.000433277303987328 -3.54664423471128E-05 0.0599427668933796"/>
      <mass value="0.841070778135659"/>
      <inertia ixx="0.0017261110801622" ixy="2.52746264980217E-06" ixz="-3.67690303614961E-05" iyy="0.00170987405835604" iyz="1.67996364994424E-06" izz="0.000904023422915791"/>
    </inertial>
    <visual>
      <origin rpy="0 0 0" xyz="0 0 0"/>
      <geometry>
        <mesh filename="moderos_descriptions/rm_65_b_description/meshes/base_link.STL"/>
      </geometry>
      <material name="tr4_light_grey"/>
    </visual>
    <collision>
      <origin rpy="0 0 0" xyz="0 0 0"/>
      <geometry>
        <mesh filename="moderos_descriptions/rm_65_b_description/meshes/base_link.STL"/>
      </geometry>
    </collision>
  </link>
  <joint name="left_arm_mount_joint" type="fixed">
    <parent link="torso"/>
    <child link="left_arm_base_link"/>
    <origin rpy="-3.137776 -1.570000 -0.004613" xyz="0.025635 -0.158686 0.942540"/>
  </joint>
  <!-- Link1 -->
  <link name="left_arm_Link1">
    <inertial>
      <origin rpy="0 0 0" xyz="1.2226305431569E-08 0.0211079974844683 -0.0251854220842269"/>
      <mass value="0.593563443690403"/>
      <inertia ixx="0.00126614120341847" ixy="-1.294980943835E-08" ixz="-9.80120923066996E-09" iyy="0.00118168178300364" iyz="-0.00021121727444415" izz="0.00056135241627747"/>
    </inertial>
    <visual>
      <origin rpy="0 0 0" xyz="0 0 0"/>
      <geometry>
        <mesh filename="moderos_descriptions/rm_65_b_description/meshes/link1.STL"/>
      </geometry>
      <material name="tr4_light_grey"/>
    </visual>
    <collision>
      <origin rpy="0 0 0" xyz="0 0 0"/>
      <geometry>
        <mesh filename="moderos_descriptions/rm_65_b_description/meshes/link1.STL"/>
      </geometry>
    </collision>
  </link>
  <!-- Joint1 -->
  <joint name="left_arm_joint1" type="revolute">
    <origin rpy="0 0 0" xyz="0 0 0.2405"/>
    <parent link="left_arm_base_link"/>
    <child link="left_arm_Link1"/>
    <axis xyz="0 0 1"/>
    <limit effort="60" lower="-3.1" upper="3.1" velocity="3.14"/>
  </joint>
  <!-- Link2 -->
  <link name="left_arm_Link2">
    <inertial>
      <origin rpy="0 0 0" xyz="0.152256463426163 4.75383656106654E-07 -0.00620260383607792"/>
      <mass value="0.864175046869043"/>
      <inertia ixx="0.00089150298478414" ixy="-2.23268489334765E-08" ixz="0.00156246461035015" iyy="0.00733754343083901" iyz="6.28110889329165E-09" izz="0.00697869103915473"/>
    </inertial>
    <visual>
      <origin rpy="0 0 0" xyz="0 0 0"/>
      <geometry>
        <mesh filename="moderos_descriptions/rm_65_b_description/meshes/link2.STL"/>
      </geometry>
      <material name="tr4_light_grey"/>
    </visual>
    <collision>
      <origin rpy="0 0 0" xyz="0 0 0"/>
      <geometry>
        <mesh filename="moderos_descriptions/rm_65_b_description/meshes/link2.STL"/>
      </geometry>
    </collision>
  </link>
  <!-- Joint2 -->
  <joint name="left_arm_joint2" type="revolute">
    <origin rpy="1.5708 -1.5708 0" xyz="0 0 0"/>
    <parent link="left_arm_Link1"/>
    <child link="left_arm_Link2"/>
    <axis xyz="0 0 1"/>
    <limit effort="60" lower="-2.268" upper="2.268" velocity="3.14"/>
  </joint>
  <!-- Link3 -->
  <link name="left_arm_Link3">
    <inertial>
      <origin rpy="0 0 0" xyz="5.05312670989961E-06 -0.0595925663694732 0.010569069212336"/>
      <mass value="0.289633681624654"/>
      <inertia ixx="0.00063737100450158" ixy="-7.05261293649751E-08" ixz="-3.86643272239426E-08" iyy="0.00015648388095025" iyz="-0.00014461035994916" izz="0.000614178164773085"/>
    </inertial>
    <visual>
      <origin rpy="0 0 0" xyz="0 0 0"/>
      <geometry>
        <mesh filename="moderos_descriptions/rm_65_b_description/meshes/link3.STL"/>
      </geometry>
      <material name="tr4_light_grey"/>
    </visual>
    <collision>
      <origin rpy="0 0 0" xyz="0 0 0"/>
      <geometry>
        <mesh filename="moderos_descriptions/rm_65_b_description/meshes/link3.STL"/>
      </geometry>
    </collision>
  </link>
  <!-- Joint3 -->
  <joint name="left_arm_joint3" type="revolute">
    <origin rpy="0 0 1.5708" xyz="0.256 0 0"/>
    <parent link="left_arm_Link2"/>
    <child link="left_arm_Link3"/>
    <axis xyz="0 0 1"/>
    <limit effort="30" lower="-2.355" upper="2.355" velocity="3.92"/>
  </joint>
  <!-- Link4 -->
  <link name="left_arm_Link4">
    <inertial>
      <origin rpy="0 0 0" xyz="1.15516617405898E-06 -0.0180424468598241 -0.0215394748352687"/>
      <mass value="0.239419768320061"/>
      <inertia ixx="0.000285938919722783" ixy="3.07101359163101E-09" ixz="-2.21994118981953E-09" iyy="0.000262727540304212" iyz="4.4236583260078E-05" izz="0.000119888082791859"/>
    </inertial>
    <visual>
      <origin rpy="0 0 0" xyz="0 0 0"/>
      <geometry>
        <mesh filename="moderos_descriptions/rm_65_b_description/meshes/link4.STL"/>
      </geometry>
      <material name="tr4_light_grey"/>
    </visual>
    <collision>
      <origin rpy="0 0 0" xyz="0 0 0"/>
      <geometry>
        <mesh filename="moderos_descriptions/rm_65_b_description/meshes/link4.STL"/>
      </geometry>
    </collision>
  </link>
  <!-- Joint4 -->
  <joint name="left_arm_joint4" type="revolute">
    <origin rpy="1.5708 0 0" xyz="0 -0.21 0"/>
    <parent link="left_arm_Link3"/>
    <child link="left_arm_Link4"/>
    <axis xyz="0 0 1"/>
    <limit effort="10" lower="-3.1" upper="3.1" velocity="3.92"/>
  </joint>
  <!-- Link5 -->
  <link name="left_arm_Link5">
    <inertial>
      <origin rpy="0 0 0" xyz="3.19794786262152E-06 -0.0593808368101458 0.00736804250989326"/>
      <mass value="0.218799761431678"/>
      <inertia ixx="0.000350540363914072" ixy="-3.41781619975602E-08" ixz="-1.77056457224373E-08" iyy="0.000104927867487581" iyz="-7.82431228461971E-05" izz="0.000334482418423629"/>
    </inertial>
    <visual>
      <origin rpy="0 0 0" xyz="0 0 0"/>
      <geometry>
        <mesh filename="moderos_descriptions/rm_65_b_description/meshes/link5.STL"/>
      </geometry>
      <material name="tr4_light_grey"/>
    </visual>
    <collision>
      <origin rpy="0 0 0" xyz="0 0 0"/>
      <geometry>
        <mesh filename="moderos_descriptions/rm_65_b_description/meshes/link5.STL"/>
      </geometry>
    </collision>
  </link>
  <!-- Joint5 -->
  <joint name="left_arm_joint5" type="revolute">
    <origin rpy="-1.5708 0 0" xyz="0 0 0"/>
    <parent link="left_arm_Link4"/>
    <child link="left_arm_Link5"/>
    <axis xyz="0 0 1"/>
    <limit effort="10" lower="-2.233" upper="2.233" velocity="3.92"/>
  </joint>
  <!-- Link6 -->
  <link name="left_arm_Link6">
    <inertial>
      <origin rpy="0 0 0" xyz="0.000714234511756999 -0.000396718732824521 -0.0126723660946126"/>
      <mass value="0.0649018034311231"/>
      <inertia ixx="2.02766547502765E-05" ixy="-1.32505200276849E-06" ixz="-2.5845091522508E-08" iyy="1.87986725225022E-05" iyz="3.39471452125439E-09" izz="3.17885459163081E-05"/>
    </inertial>
    <visual>
      <origin rpy="0 0 0" xyz="0 0 0"/>
      <geometry>
        <mesh filename="moderos_descriptions/rm_65_b_description/meshes/link6.STL"/>
      </geometry>
      <material name="tr4_light_grey"/>
    </visual>
    <collision>
      <origin rpy="0 0 0" xyz="0 0 0"/>
      <geometry>
        <mesh filename="moderos_descriptions/rm_65_b_description/meshes/link6.STL"/>
      </geometry>
    </collision>
  </link>
  <!-- Joint6 -->
  <joint name="left_arm_joint6" type="revolute">
    <origin rpy="1.5708 0 0" xyz="0 -0.144 0"/>
    <parent link="left_arm_Link5"/>
    <child link="left_arm_Link6"/>
    <axis xyz="0 0 1"/>
    <limit effort="10" lower="-6.28" upper="6.28" velocity="3.92"/>
  </joint>
  <!-- 与上游机械臂的固定连接 -->
  <joint name="lefthand_eef_joint" type="fixed">
    <parent link="left_arm_Link6"/>
    <child link="lefthand_base_link"/>
    <origin rpy="0 0 0" xyz="0 0 0"/>
  </joint>
  <!-- === Base === -->
  <link name="lefthand_base_link">
    <inertial>
      <origin rpy="0 0 0" xyz="-0.00478670623240344 0.00141981128680177 0.0505239077176535"/>
      <mass value="0.0306792270125578"/>
      <inertia ixx="2.2266510056133E-05" ixy="-2.6318583761649E-07" ixz="1.83638592892823E-07" iyy="1.55367220548952E-05" iyz="1.26586485241028E-06" izz="8.58669326263691E-06"/>
    </inertial>
    <visual>
      <origin rpy="0 0 0" xyz="0 0 0"/>
      <geometry>
        <mesh filename="moderos_descriptions/brainco-lefthand-URDF-V2/meshes/base_link.STL"/>
      </geometry>
      <material name="tr4_black_metal" />
    </visual>
    <collision>
      <origin rpy="0 0 0" xyz="0 0 0"/>
      <geometry>
        <mesh filename="moderos_descriptions/brainco-lefthand-URDF-V2/meshes/base_link.STL"/>
      </geometry>
    </collision>
  </link>
  <!-- === Thumb === -->
  <link name="lefthand_thumb_metacarpal_link">
    <inertial>
      <origin rpy="0 0 0" xyz="1.52303696287041E-05 -0.00707240283482268 -0.00420839832903629"/>
      <mass value="0.00116017537569294"/>
      <inertia ixx="1.59238866130872E-07" ixy="4.69114607598504E-09" ixz="4.93233725002147E-10" iyy="1.60911967461756E-07" iyz="1.48144948560702E-08" izz="5.13544258620214E-08"/>
    </inertial>
    <visual>
      <origin rpy="0 0 0" xyz="0 0 0"/>
      <geometry>
        <mesh filename="moderos_descriptions/brainco-lefthand-URDF-V2/meshes/thumb_metacarpal_Link.STL"/>
      </geometry>
      <material name="tr4_black_metal" />
    </visual>
    <collision>
      <origin rpy="0 0 0" xyz="0 0 0"/>
      <geometry>
        <mesh filename="moderos_descriptions/brainco-lefthand-URDF-V2/meshes/thumb_metacarpal_Link.STL"/>
      </geometry>
    </collision>
  </link>
  <joint name="lefthand_thumb_metacarpal_joint" type="revolute">
    <origin rpy="0 0 0.16787" xyz="0.0045 -0.019 0.027825"/>
    <parent link="lefthand_base_link"/>
    <child link="lefthand_thumb_metacarpal_link"/>
    <axis xyz="0 0 1"/>
    <limit effort="0.5" lower="0" upper="1.5184" velocity="2.6175"/>
  </joint>
  <link name="lefthand_thumb_proximal_link">
    <inertial>
      <origin rpy="0 0 0" xyz="-3.41001513141231E-07 -0.0250090688174992 -0.0017505675193664"/>
      <mass value="0.0134370512314493"/>
      <inertia ixx="3.23318665954068E-06" ixy="1.54514148596361E-10" ixz="1.24375216968143E-11" iyy="5.64488567432875E-07" iyz="-5.04309083812215E-08" izz="3.39928573090826E-06"/>
    </inertial>
    <visual>
      <origin rpy="0 0 0" xyz="0 0 0"/>
      <geometry>
        <!-- 注意：网格文件名为 thump_（导出时拼写如此），保持不变 -->
        <mesh filename="moderos_descriptions/brainco-lefthand-URDF-V2/meshes/thump_proximal_Link.STL"/>
      </geometry>
      <material name="tr4_black_metal" />
    </visual>
    <collision>
      <origin rpy="0 0 0" xyz="0 0 0"/>
      <geometry>
        <mesh filename="moderos_descriptions/brainco-lefthand-URDF-V2/meshes/thump_proximal_Link.STL"/>
      </geometry>
    </collision>
  </link>
  <joint name="lefthand_thumb_proximal_joint" type="revolute">
    <origin rpy="-0.17488 0.23736 -0.16787" xyz="0 -0.014227 0"/>
    <parent link="lefthand_thumb_metacarpal_link"/>
    <child link="lefthand_thumb_proximal_link"/>
    <axis xyz="1 0 0"/>
    <limit effort="1.1" lower="-1.0472" upper="0" velocity="2.5303"/>
  </joint>
  <link name="lefthand_thumb_distal_link">
    <inertial>
      <origin rpy="0 0 0" xyz="1.65618684180163E-07 -0.0117550891981017 1.1366609064185E-05"/>
      <mass value="0.00417177764035474"/>
      <inertia ixx="1.6780928553031E-07" ixy="1.91856562375275E-11" ixz="2.694752026736E-12" iyy="1.15357239984326E-07" iyz="-1.25182560702848E-08" izz="2.1956615213811E-07"/>
    </inertial>
    <visual>
      <origin rpy="0 0 0" xyz="0 0 0"/>
      <geometry>
        <mesh filename="moderos_descriptions/brainco-lefthand-URDF-V2/meshes/thump_distal_Link.STL"/>
      </geometry>
      <material name="tr4_black_metal" />
    </visual>
    <collision>
      <origin rpy="0 0 0" xyz="0 0 0"/>
      <geometry>
        <mesh filename="moderos_descriptions/brainco-lefthand-URDF-V2/meshes/thump_distal_Link.STL"/>
      </geometry>
    </collision>
  </link>
  <joint name="lefthand_thumb_distal_joint" type="revolute">
    <origin rpy="0 0 0" xyz="0 -0.052 0"/>
    <parent link="lefthand_thumb_proximal_link"/>
    <child link="lefthand_thumb_distal_link"/>
    <axis xyz="1 0 0"/>
    <limit effort="1.1" lower="-1.0472" upper="0" velocity="2.5303"/>
  </joint>
  <link name="lefthand_thumb_tip">
    <inertial>
      <origin rpy="0 0 0" xyz="-4.85722573273506E-17 -4.16333634234434E-17 -3.46944695195361E-18"/>
      <mass value="6.54498469497874E-08"/>
      <inertia ixx="1.63624617374468E-15" ixy="0" ixz="0" iyy="1.63624617374468E-15" iyz="3.85185988877447E-33" izz="1.63624617374468E-15"/>
    </inertial>
    <visual>
      <origin rpy="0 0 0" xyz="0 0 0"/>
      <geometry>
        <mesh filename="moderos_descriptions/brainco-lefthand-URDF-V2/meshes/thump_tip_Link.STL"/>
      </geometry>
      <material name="tr4_black_metal" />
    </visual>
    <collision>
      <origin rpy="0 0 0" xyz="0 0 0"/>
      <geometry>
        <mesh filename="moderos_descriptions/brainco-lefthand-URDF-V2/meshes/thump_tip_Link.STL"/>
      </geometry>
    </collision>
  </link>
  <joint name="lefthand_thumb_tip_joint" type="revolute">
    <origin rpy="0.06675 0 0" xyz="0 -0.026529 -0.0017734"/>
    <parent link="lefthand_thumb_distal_link"/>
    <child link="lefthand_thumb_tip"/>
    <axis xyz="1 0 0"/>
    <limit effort="1.1" lower="0" upper="1.2741" velocity="2.5303"/>
  </joint>
  <!-- === Index === -->
  <link name="lefthand_index_proximal_link">
    <inertial>
      <origin rpy="0 0 0" xyz="-0.00223538742601201 -3.80544615179515E-06 0.0176439423080373"/>
      <mass value="0.00195456379953392"/>
      <inertia ixx="2.51863526940901E-07" ixy="-3.10934654014144E-11" ixz="-6.36901300651623E-09" iyy="2.36343210839019E-07" iyz="-1.71663811116816E-10" izz="9.30397543724724E-08"/>
    </inertial>
    <visual>
      <origin rpy="0 0 0" xyz="0 0 0"/>
      <geometry>
        <mesh filename="moderos_descriptions/brainco-lefthand-URDF-V2/meshes/index_proximal_Link.STL"/>
      </geometry>
      <material name="tr4_black_metal" />
    </visual>
    <collision>
      <origin rpy="0 0 0" xyz="0 0 0"/>
      <geometry>
        <mesh filename="moderos_descriptions/brainco-lefthand-URDF-V2/meshes/index_proximal_Link.STL"/>
      </geometry>
    </collision>
  </link>
  <joint name="lefthand_index_proximal_joint" type="revolute">
    <origin rpy="0.11819 0.14743 0.17422" xyz="-0.0021349 -0.029578 0.080876"/>
    <parent link="lefthand_base_link"/>
    <child link="lefthand_index_proximal_link"/>
    <axis xyz="0 1 0"/>
    <limit effort="2" lower="0" upper="1.4661" velocity="2.2685"/>
  </joint>
  <link name="lefthand_index_distal_link">
    <inertial>
      <origin rpy="0 0 0" xyz="0.00418325886379583 -8.45607972810303E-08 0.0153641608762859"/>
      <mass value="0.00406279694173471"/>
      <inertia ixx="3.65266271559531E-07" ixy="5.6892108332606E-13" ixz="-1.02335061442931E-07" iyy="3.96961530855654E-07" iyz="7.7396138584356E-13" izz="1.04991723103838E-07"/>
    </inertial>
    <visual>
      <origin rpy="0 0 0" xyz="0 0 0"/>
      <geometry>
        <mesh filename="moderos_descriptions/brainco-lefthand-URDF-V2/meshes/index_distal_Link.STL"/>
      </geometry>
      <material name="tr4_black_metal" />
    </visual>
    <collision>
      <origin rpy="0 0 0" xyz="0 0 0"/>
      <geometry>
        <mesh filename="moderos_descriptions/brainco-lefthand-URDF-V2/meshes/index_distal_Link.STL"/>
      </geometry>
    </collision>
  </link>
  <joint name="lefthand_index_distal_joint" type="revolute">
    <origin rpy="0 0 0" xyz="0 0 0.032"/>
    <parent link="lefthand_index_proximal_link"/>
    <child link="lefthand_index_distal_link"/>
    <axis xyz="0 1 0"/>
    <limit effort="2" lower="0" upper="1.693" velocity="2.2685"/>
  </joint>
  <link name="lefthand_index_tip">
    <inertial>
      <origin rpy="0 0 0" xyz="6.69832245225876E-13 9.73495589695617E-12 2.23557283796083E-13"/>
      <mass value="6.54498469497874E-08"/>
      <inertia ixx="1.63624617374468E-15" ixy="6.16297582203915E-32" ixz="0" iyy="1.63624617374468E-15" iyz="2.46519032881566E-32" izz="1.63624617374468E-15"/>
    </inertial>
    <visual>
      <origin rpy="0 0 0" xyz="0 0 0"/>
      <geometry>
        <mesh filename="moderos_descriptions/brainco-lefthand-URDF-V2/meshes/index_tip_Link.STL"/>
      </geometry>
      <material name="tr4_black_metal" />
    </visual>
    <collision>
      <origin rpy="0 0 0" xyz="0 0 0"/>
      <geometry>
        <mesh filename="moderos_descriptions/brainco-lefthand-URDF-V2/meshes/index_tip_Link.STL"/>
      </geometry>
    </collision>
  </link>
  <joint name="lefthand_index_tip_joint" type="revolute">
    <origin rpy="0 0.48723 0" xyz="0.011097 0 0.035739"/>
    <parent link="lefthand_index_distal_link"/>
    <child link="lefthand_index_tip"/>
    <axis xyz="0 1 0"/>
    <limit effort="1" lower="1" upper="1" velocity="1"/>
  </joint>
  <!-- === Middle === -->
  <link name="lefthand_middle_proximal_link">
    <inertial>
      <origin rpy="0 0 0" xyz="-0.00222419445309931 -3.61990820813788E-06 0.0203049526045434"/>
      <mass value="0.00232190897281875"/>
      <inertia ixx="3.66885320718611E-07" ixy="-3.64303343703497E-11" ixz="-9.77995332041374E-09" iyy="3.5252138716754E-07" iyz="-2.58098211906238E-10" izz="1.12242284171831E-07"/>
    </inertial>
    <visual>
      <origin rpy="0 0 0" xyz="0 0 0"/>
      <geometry>
        <mesh filename="moderos_descriptions/brainco-lefthand-URDF-V2/meshes/middle_proximal_Link.STL"/>
      </geometry>
      <material name="tr4_black_metal" />
    </visual>
    <collision>
      <origin rpy="0 0 0" xyz="0 0 0"/>
      <geometry>
        <mesh filename="moderos_descriptions/brainco-lefthand-URDF-V2/meshes/middle_proximal_Link.STL"/>
      </geometry>
    </collision>
  </link>
  <joint name="lefthand_middle_proximal_joint" type="revolute">
    <origin rpy="0.039468 0.1483 0.057975" xyz="-0.0045935 -0.010061 0.084993"/>
    <parent link="lefthand_base_link"/>
    <child link="lefthand_middle_proximal_link"/>
    <axis xyz="0 1 0"/>
    <limit effort="2" lower="0" upper="1.4661" velocity="2.2685"/>
  </joint>
  <link name="lefthand_middle_distal_link">
    <inertial>
      <origin rpy="0 0 0" xyz="0.00269750139301864 3.27210103738713E-07 0.0183076461156786"/>
      <mass value="0.00491865752250277"/>
      <inertia ixx="5.88341898887764E-07" ixy="-1.34073376317885E-12" ixz="-1.04743131832206E-07" iyy="6.07118927271626E-07" iyz="-1.31817421243225E-11" izz="1.11265454837883E-07"/>
    </inertial>
    <visual>
      <origin rpy="0 0 0" xyz="0 0 0"/>
      <geometry>
        <mesh filename="moderos_descriptions/brainco-lefthand-URDF-V2/meshes/middle_distal_Link.STL"/>
      </geometry>
      <material name="tr4_black_metal" />
    </visual>
    <collision>
      <origin rpy="0 0 0" xyz="0 0 0"/>
      <geometry>
        <mesh filename="moderos_descriptions/brainco-lefthand-URDF-V2/meshes/middle_distal_Link.STL"/>
      </geometry>
    </collision>
  </link>
  <joint name="lefthand_middle_distal_joint" type="revolute">
    <origin rpy="0 0.12654 0" xyz="0 0 0.037"/>
    <parent link="lefthand_middle_proximal_link"/>
    <child link="lefthand_middle_distal_link"/>
    <axis xyz="0 1 0"/>
    <limit effort="2" lower="0" upper="1.693" velocity="2.2685"/>
  </joint>
  <link name="lefthand_middle_tip">
    <inertial>
      <origin rpy="0 0 0" xyz="3.12250225675825E-16 -1.90819582357449E-17 5.55111512312578E-17"/>
      <mass value="6.54498469497874E-08"/>
      <inertia ixx="1.63624617374468E-15" ixy="0" ixz="-4.93038065763132E-32" iyy="1.63624617374468E-15" iyz="9.24446373305873E-33" izz="1.63624617374468E-15"/>
    </inertial>
    <visual>
      <origin rpy="0 0 0" xyz="0 0 0"/>
      <geometry>
        <mesh filename="moderos_descriptions/brainco-lefthand-URDF-V2/meshes/middle_tip_Link.STL"/>
      </geometry>
      <material name="tr4_black_metal" />
    </visual>
    <collision>
      <origin rpy="0 0 0" xyz="0 0 0"/>
      <geometry>
        <mesh filename="moderos_descriptions/brainco-lefthand-URDF-V2/meshes/middle_tip_Link.STL"/>
      </geometry>
    </collision>
  </link>
  <joint name="lefthand_middle_tip_joint" type="revolute">
    <origin rpy="0 0.34907 0" xyz="0.0073534 0 0.041703"/>
    <parent link="lefthand_middle_distal_link"/>
    <child link="lefthand_middle_tip"/>
    <axis xyz="0 1 0"/>
    <limit effort="1" lower="1" upper="1" velocity="1"/>
  </joint>
  <!-- === Ring === -->
  <link name="lefthand_ring_proximal_link">
    <inertial>
      <origin rpy="0 0 0" xyz="-0.00234461360118865 -5.32058096490429E-06 0.0191785931520923"/>
      <mass value="0.0021499545886434"/>
      <inertia ixx="3.14182210853629E-07" ixy="-3.44825864493775E-11" ixz="-7.78011903077362E-09" iyy="2.97623388067888E-07" iyz="-2.45023710126379E-10" izz="1.02120946203075E-07"/>
    </inertial>
    <visual>
      <origin rpy="0 0 0" xyz="0 0 0"/>
      <geometry>
        <mesh filename="moderos_descriptions/brainco-lefthand-URDF-V2/meshes/ring_proximal_Link.STL"/>
      </geometry>
      <material name="tr4_black_metal" />
    </visual>
    <collision>
      <origin rpy="0 0 0" xyz="0 0 0"/>
      <geometry>
        <mesh filename="moderos_descriptions/brainco-lefthand-URDF-V2/meshes/ring_proximal_Link.STL"/>
      </geometry>
    </collision>
  </link>
  <joint name="lefthand_ring_proximal_joint" type="revolute">
    <origin rpy="-0.039462 0.14721 -0.057932" xyz="-0.0046877 0.010026 0.083982"/>
    <parent link="lefthand_base_link"/>
    <child link="lefthand_ring_proximal_link"/>
    <axis xyz="0 1 0"/>
    <limit effort="2" lower="0" upper="1.4661" velocity="2.2685"/>
  </joint>
  <link name="lefthand_ring_distal_link">
    <inertial>
      <origin rpy="0 0 0" xyz="0.00249839540877306 -2.78996376348872E-08 0.0177055538603162"/>
      <mass value="0.00466284157402773"/>
      <inertia ixx="5.40369389752843E-07" ixy="-3.16120850919557E-12" ixz="-9.71738751449029E-08" iyy="5.56818359755755E-07" iyz="-5.08675656942151E-12" izz="1.03096676549004E-07"/>
    </inertial>
    <visual>
      <origin rpy="0 0 0" xyz="0 0 0"/>
      <geometry>
        <mesh filename="moderos_descriptions/brainco-lefthand-URDF-V2/meshes/ring_distal_Link.STL"/>
      </geometry>
      <material name="tr4_black_metal" />
    </visual>
    <collision>
      <origin rpy="0 0 0" xyz="0 0 0"/>
      <geometry>
        <mesh filename="moderos_descriptions/brainco-lefthand-URDF-V2/meshes/ring_distal_Link.STL"/>
      </geometry>
    </collision>
  </link>
  <joint name="lefthand_ring_distal_joint" type="revolute">
    <origin rpy="0 0.12654 0" xyz="0 0 0.035"/>
    <parent link="lefthand_ring_proximal_link"/>
    <child link="lefthand_ring_distal_link"/>
    <axis xyz="0 1 0"/>
    <limit effort="2" lower="0" upper="1.693" velocity="2.2685"/>
  </joint>
  <link name="lefthand_ring_tip">
    <inertial>
      <origin rpy="0 0 0" xyz="3.05311331771918E-16 3.46944695195361E-17 2.77555756156289E-17"/>
      <mass value="6.54498469497874E-08"/>
      <inertia ixx="1.63624617374468E-15" ixy="-1.23259516440783E-32" ixz="0" iyy="1.63624617374468E-15" iyz="0" izz="1.63624617374468E-15"/>
    </inertial>
    <visual>
      <origin rpy="0 0 0" xyz="0 0 0"/>
      <geometry>
        <mesh filename="moderos_descriptions/brainco-lefthand-URDF-V2/meshes/ring_tip_Link.STL"/>
      </geometry>
      <material name="tr4_black_metal" />
    </visual>
    <collision>
      <origin rpy="0 0 0" xyz="0 0 0"/>
      <geometry>
        <mesh filename="moderos_descriptions/brainco-lefthand-URDF-V2/meshes/ring_tip_Link.STL"/>
      </geometry>
    </collision>
  </link>
  <joint name="lefthand_ring_tip_joint" type="revolute">
    <origin rpy="0 0.34907 0" xyz="0.0071824 0 0.040734"/>
    <parent link="lefthand_ring_distal_link"/>
    <child link="lefthand_ring_tip"/>
    <axis xyz="0 1 0"/>
    <limit effort="1" lower="1" upper="1" velocity="1"/>
  </joint>
  <!-- === Pinky === -->
  <link name="lefthand_pinky_proximal_link">
    <inertial>
      <origin rpy="0 0 0" xyz="-0.00213266608574047 -7.02260316783054E-06 0.0160680350593264"/>
      <mass value="0.00173865891957665"/>
      <inertia ixx="1.97554078210582E-07" ixy="-1.34133676966608E-11" ixz="-4.58601823842206E-09" iyy="1.82022483454667E-07" iyz="-1.01838144940489E-10" izz="8.21758160050774E-08"/>
    </inertial>
    <visual>
      <origin rpy="0 0 0" xyz="0 0 0"/>
      <geometry>
        <mesh filename="moderos_descriptions/brainco-lefthand-URDF-V2/meshes/pinky_proximal_Link.STL"/>
      </geometry>
      <material name="tr4_black_metal" />
    </visual>
    <collision>
      <origin rpy="0 0 0" xyz="0 0 0"/>
      <geometry>
        <mesh filename="moderos_descriptions/brainco-lefthand-URDF-V2/meshes/pinky_proximal_Link.STL"/>
      </geometry>
    </collision>
  </link>
  <joint name="lefthand_pinky_proximal_joint" type="revolute">
    <origin rpy="-0.11815 0.14491 -0.17392" xyz="-0.0023733 0.029356 0.078694"/>
    <parent link="lefthand_base_link"/>
    <child link="lefthand_pinky_proximal_link"/>
    <axis xyz="0 1 0"/>
    <limit effort="2" lower="0" upper="1.4661" velocity="2.2685"/>
  </joint>
  <link name="lefthand_pinky_distal_link">
    <inertial>
      <origin rpy="0 0 0" xyz="0.00398562130468761 -8.08551930131518E-08 0.014106664402408"/>
      <mass value="0.0037573321475203"/>
      <inertia ixx="2.88250623683654E-07" ixy="-1.4286564858765E-12" ixz="-7.78112273929214E-08" iyy="3.10833114148178E-07" iyz="1.51641220464989E-13" izz="9.12872269672051E-08"/>
    </inertial>
    <visual>
      <origin rpy="0 0 0" xyz="0 0 0"/>
      <geometry>
        <mesh filename="moderos_descriptions/brainco-lefthand-URDF-V2/meshes/pinky_distal_Link.STL"/>
      </geometry>
      <material name="tr4_black_metal" />
    </visual>
    <collision>
      <origin rpy="0 0 0" xyz="0 0 0"/>
      <geometry>
        <mesh filename="moderos_descriptions/brainco-lefthand-URDF-V2/meshes/pinky_distal_Link.STL"/>
      </geometry>
    </collision>
  </link>
  <joint name="lefthand_pinky_distal_joint" type="revolute">
    <origin rpy="0 0 0" xyz="0 0 0.029"/>
    <parent link="lefthand_pinky_proximal_link"/>
    <child link="lefthand_pinky_distal_link"/>
    <axis xyz="0 1 0"/>
    <limit effort="2" lower="0" upper="1.693" velocity="2.2685"/>
  </joint>
  <link name="lefthand_pinky_tip">
    <inertial>
      <origin rpy="0 0 0" xyz="2.63677968348475E-16 -4.09394740330526E-16 5.55111512312578E-17"/>
      <mass value="6.54498469497874E-08"/>
      <inertia ixx="1.63624617374468E-15" ixy="1.23259516440783E-32" ixz="0" iyy="1.63624617374468E-15" iyz="-2.46519032881566E-32" izz="1.63624617374468E-15"/>
    </inertial>
    <visual>
      <origin rpy="0 0 0" xyz="0 0 0"/>
      <geometry>
        <mesh filename="moderos_descriptions/brainco-lefthand-URDF-V2/meshes/pinky_tip_Link.STL"/>
      </geometry>
      <material name="tr4_black_metal" />
    </visual>
    <collision>
      <origin rpy="0 0 0" xyz="0 0 0"/>
      <geometry>
        <mesh filename="moderos_descriptions/brainco-lefthand-URDF-V2/meshes/pinky_tip_Link.STL"/>
      </geometry>
    </collision>
  </link>
  <joint name="lefthand_pinky_tip_joint" type="revolute">
    <origin rpy="0 0.4756 0" xyz="0.010221 0 0.032918"/>
    <parent link="lefthand_pinky_distal_link"/>
    <child link="lefthand_pinky_tip"/>
    <axis xyz="0 1 0"/>
    <limit effort="1" lower="1" upper="1" velocity="1"/>
  </joint>
  <!-- Base Link -->
  <link name="right_arm_base_link">
    <inertial>
      <origin rpy="0 0 0" xyz="-0.000433277303987328 -3.54664423471128E-05 0.0599427668933796"/>
      <mass value="0.841070778135659"/>
      <inertia ixx="0.0017261110801622" ixy="2.52746264980217E-06" ixz="-3.67690303614961E-05" iyy="0.00170987405835604" iyz="1.67996364994424E-06" izz="0.000904023422915791"/>
    </inertial>
    <visual>
      <origin rpy="0 0 0" xyz="0 0 0"/>
      <geometry>
        <mesh filename="moderos_descriptions/rm_65_b_description/meshes/base_link.STL"/>
      </geometry>
      <material name="tr4_black_metal" />
    </visual>
    <collision>
      <origin rpy="0 0 0" xyz="0 0 0"/>
      <geometry>
        <mesh filename="moderos_descriptions/rm_65_b_description/meshes/base_link.STL"/>
      </geometry>
    </collision>
  </link>
  <joint name="right_arm_mount_joint" type="fixed">
    <parent link="torso"/>
    <child link="right_arm_base_link"/>
    <origin rpy="-2.036165 -1.569019 2.035368" xyz="-0.025635 -0.158686 0.942540"/>
  </joint>
  <!-- Link1 -->
  <link name="right_arm_Link1">
    <inertial>
      <origin rpy="0 0 0" xyz="1.2226305431569E-08 0.0211079974844683 -0.0251854220842269"/>
      <mass value="0.593563443690403"/>
      <inertia ixx="0.00126614120341847" ixy="-1.294980943835E-08" ixz="-9.80120923066996E-09" iyy="0.00118168178300364" iyz="-0.00021121727444415" izz="0.00056135241627747"/>
    </inertial>
    <visual>
      <origin rpy="0 0 0" xyz="0 0 0"/>
      <geometry>
        <mesh filename="moderos_descriptions/rm_65_b_description/meshes/link1.STL"/>
      </geometry>
      <material name="tr4_light_grey"/>
    </visual>
    <collision>
      <origin rpy="0 0 0" xyz="0 0 0"/>
      <geometry>
        <mesh filename="moderos_descriptions/rm_65_b_description/meshes/link1.STL"/>
      </geometry>
    </collision>
  </link>
  <!-- Joint1 -->
  <joint name="right_arm_joint1" type="revolute">
    <origin rpy="0 0 0" xyz="0 0 0.2405"/>
    <parent link="right_arm_base_link"/>
    <child link="right_arm_Link1"/>
    <axis xyz="0 0 1"/>
    <limit effort="60" lower="-3.1" upper="3.1" velocity="3.14"/>
  </joint>
  <!-- Link2 -->
  <link name="right_arm_Link2">
    <inertial>
      <origin rpy="0 0 0" xyz="0.152256463426163 4.75383656106654E-07 -0.00620260383607792"/>
      <mass value="0.864175046869043"/>
      <inertia ixx="0.00089150298478414" ixy="-2.23268489334765E-08" ixz="0.00156246461035015" iyy="0.00733754343083901" iyz="6.28110889329165E-09" izz="0.00697869103915473"/>
    </inertial>
    <visual>
      <origin rpy="0 0 0" xyz="0 0 0"/>
      <geometry>
        <mesh filename="moderos_descriptions/rm_65_b_description/meshes/link2.STL"/>
      </geometry>
      <material name="tr4_light_grey"/>
    </visual>
    <collision>
      <origin rpy="0 0 0" xyz="0 0 0"/>
      <geometry>
        <mesh filename="moderos_descriptions/rm_65_b_description/meshes/link2.STL"/>
      </geometry>
    </collision>
  </link>
  <!-- Joint2 -->
  <joint name="right_arm_joint2" type="revolute">
    <origin rpy="1.5708 -1.5708 0" xyz="0 0 0"/>
    <parent link="right_arm_Link1"/>
    <child link="right_arm_Link2"/>
    <axis xyz="0 0 1"/>
    <limit effort="60" lower="-2.268" upper="2.268" velocity="3.14"/>
  </joint>
  <!-- Link3 -->
  <link name="right_arm_Link3">
    <inertial>
      <origin rpy="0 0 0" xyz="5.05312670989961E-06 -0.0595925663694732 0.010569069212336"/>
      <mass value="0.289633681624654"/>
      <inertia ixx="0.00063737100450158" ixy="-7.05261293649751E-08" ixz="-3.86643272239426E-08" iyy="0.00015648388095025" iyz="-0.00014461035994916" izz="0.000614178164773085"/>
    </inertial>
    <visual>
      <origin rpy="0 0 0" xyz="0 0 0"/>
      <geometry>
        <mesh filename="moderos_descriptions/rm_65_b_description/meshes/link3.STL"/>
      </geometry>
      <material name="tr4_light_grey"/>
    </visual>
    <collision>
      <origin rpy="0 0 0" xyz="0 0 0"/>
      <geometry>
        <mesh filename="moderos_descriptions/rm_65_b_description/meshes/link3.STL"/>
      </geometry>
    </collision>
  </link>
  <!-- Joint3 -->
  <joint name="right_arm_joint3" type="revolute">
    <origin rpy="0 0 1.5708" xyz="0.256 0 0"/>
    <parent link="right_arm_Link2"/>
    <child link="right_arm_Link3"/>
    <axis xyz="0 0 1"/>
    <limit effort="30" lower="-2.355" upper="2.355" velocity="3.92"/>
  </joint>
  <!-- Link4 -->
  <link name="right_arm_Link4">
    <inertial>
      <origin rpy="0 0 0" xyz="1.15516617405898E-06 -0.0180424468598241 -0.0215394748352687"/>
      <mass value="0.239419768320061"/>
      <inertia ixx="0.000285938919722783" ixy="3.07101359163101E-09" ixz="-2.21994118981953E-09" iyy="0.000262727540304212" iyz="4.4236583260078E-05" izz="0.000119888082791859"/>
    </inertial>
    <visual>
      <origin rpy="0 0 0" xyz="0 0 0"/>
      <geometry>
        <mesh filename="moderos_descriptions/rm_65_b_description/meshes/link4.STL"/>
      </geometry>
      <material name="tr4_light_grey"/>
    </visual>
    <collision>
      <origin rpy="0 0 0" xyz="0 0 0"/>
      <geometry>
        <mesh filename="moderos_descriptions/rm_65_b_description/meshes/link4.STL"/>
      </geometry>
    </collision>
  </link>
  <!-- Joint4 -->
  <joint name="right_arm_joint4" type="revolute">
    <origin rpy="1.5708 0 0" xyz="0 -0.21 0"/>
    <parent link="right_arm_Link3"/>
    <child link="right_arm_Link4"/>
    <axis xyz="0 0 1"/>
    <limit effort="10" lower="-3.1" upper="3.1" velocity="3.92"/>
  </joint>
  <!-- Link5 -->
  <link name="right_arm_Link5">
    <inertial>
      <origin rpy="0 0 0" xyz="3.19794786262152E-06 -0.0593808368101458 0.00736804250989326"/>
      <mass value="0.218799761431678"/>
      <inertia ixx="0.000350540363914072" ixy="-3.41781619975602E-08" ixz="-1.77056457224373E-08" iyy="0.000104927867487581" iyz="-7.82431228461971E-05" izz="0.000334482418423629"/>
    </inertial>
    <visual>
      <origin rpy="0 0 0" xyz="0 0 0"/>
      <geometry>
        <mesh filename="moderos_descriptions/rm_65_b_description/meshes/link5.STL"/>
      </geometry>
      <material name="tr4_light_grey"/>
    </visual>
    <collision>
      <origin rpy="0 0 0" xyz="0 0 0"/>
      <geometry>
        <mesh filename="moderos_descriptions/rm_65_b_description/meshes/link5.STL"/>
      </geometry>
    </collision>
  </link>
  <!-- Joint5 -->
  <joint name="right_arm_joint5" type="revolute">
    <origin rpy="-1.5708 0 0" xyz="0 0 0"/>
    <parent link="right_arm_Link4"/>
    <child link="right_arm_Link5"/>
    <axis xyz="0 0 1"/>
    <limit effort="10" lower="-2.233" upper="2.233" velocity="3.92"/>
  </joint>
  <!-- Link6 -->
  <link name="right_arm_Link6">
    <inertial>
      <origin rpy="0 0 0" xyz="0.000714234511756999 -0.000396718732824521 -0.0126723660946126"/>
      <mass value="0.0649018034311231"/>
      <inertia ixx="2.02766547502765E-05" ixy="-1.32505200276849E-06" ixz="-2.5845091522508E-08" iyy="1.87986725225022E-05" iyz="3.39471452125439E-09" izz="3.17885459163081E-05"/>
    </inertial>
    <visual>
      <origin rpy="0 0 0" xyz="0 0 0"/>
      <geometry>
        <mesh filename="moderos_descriptions/rm_65_b_description/meshes/link6.STL"/>
      </geometry>
      <material name="tr4_light_grey"/>
    </visual>
    <collision>
      <origin rpy="0 0 0" xyz="0 0 0"/>
      <geometry>
        <mesh filename="moderos_descriptions/rm_65_b_description/meshes/link6.STL"/>
      </geometry>
    </collision>
  </link>
  <!-- Joint6 -->
  <joint name="right_arm_joint6" type="revolute">
    <origin rpy="1.5708 0 0" xyz="0 -0.144 0"/>
    <parent link="right_arm_Link5"/>
    <child link="right_arm_Link6"/>
    <axis xyz="0 0 1"/>
    <limit effort="10" lower="-6.28" upper="6.28" velocity="3.92"/>
  </joint>
  <!-- <xacro:zc_gripper_rev3 prefix="${prefix_right_gripper}" parent_link="${prefix_right_arm}Link6"
                 origin_xyz="0 0 0" origin_rpy="3.14 -1.57 0"/> -->
  <!-- 手和上游机械臂的固定连接 -->
  <joint name="righthand_eef_joint" type="fixed">
    <parent link="right_arm_Link6"/>
    <child link="righthand_base_link"/>
    <origin rpy="0 0 0" xyz="0 0 0"/>
  </joint>
  <!-- === Base === -->
  <link name="righthand_base_link">
    <inertial>
      <origin rpy="0 0 0" xyz="-0.00477210166218609 -0.00143682517693859 0.050518681369968"/>
      <mass value="0.0306701603277963"/>
      <inertia ixx="2.22653142417882E-05" ixy="2.619146157182E-07" ixz="1.8532221192488E-07" iyy="1.55386679883247E-05" iyz="-1.26178696418883E-06" izz="8.58493926893206E-06"/>
    </inertial>
    <visual>
      <origin rpy="0 0 0" xyz="0 0 0"/>
      <geometry>
        <mesh filename="moderos_descriptions/brainco-righthand-URDF-V2/meshes/base_link.STL"/>
      </geometry>
      <material name="tr4_black_metal" />
    </visual>
    <collision>
      <origin rpy="0 0 0" xyz="0 0 0"/>
      <geometry>
        <mesh filename="moderos_descriptions/brainco-righthand-URDF-V2/meshes/base_link.STL"/>
      </geometry>
    </collision>
  </link>
  <!-- === Thumb === -->
  <link name="righthand_thumb_metacarpal_link">
    <inertial>
      <origin rpy="0 0 0" xyz="1.51105893291988E-05 0.00707242532016975 -0.00420847293427094"/>
      <mass value="0.00116019531148996"/>
      <inertia ixx="1.59239837111329E-07" ixy="-4.69100836631313E-09" ixz="4.92933775261587E-10" iyy="1.60913456568321E-07" iyz="-1.48146725871811E-08" izz="5.13550255314669E-08"/>
    </inertial>
    <visual>
      <origin rpy="0 0 0" xyz="0 0 0"/>
      <geometry>
        <mesh filename="moderos_descriptions/brainco-righthand-URDF-V2/meshes/thumb_metacarpal_link.STL"/>
      </geometry>
      <material name="tr4_black_metal" />
    </visual>
    <collision>
      <origin rpy="0 0 0" xyz="0 0 0"/>
      <geometry>
        <mesh filename="moderos_descriptions/brainco-righthand-URDF-V2/meshes/thumb_metacarpal_link.STL"/>
      </geometry>
    </collision>
  </link>
  <joint name="righthand_thumb_metacarpal_joint" type="revolute">
    <origin rpy="0 0 -0.16787" xyz="0.005619 0.019867 0.027825"/>
    <parent link="righthand_base_link"/>
    <child link="righthand_thumb_metacarpal_link"/>
    <axis xyz="0 0 1"/>
    <limit effort="0.5" lower="-1.5184" upper="0" velocity="2.6175"/>
  </joint>
  <link name="righthand_thumb_proximal_link">
    <inertial>
      <origin rpy="0 0 0" xyz="-4.57172872239675E-07 0.0250090110844873 -0.00175049403575901"/>
      <mass value="0.013437308865305"/>
      <inertia ixx="3.23319869389856E-06" ixy="-1.19075992087717E-10" ixz="1.24443381455412E-11" iyy="5.64506002356025E-07" iyz="5.04129419740444E-08" izz="3.39928434904953E-06"/>
    </inertial>
    <visual>
      <origin rpy="0 0 0" xyz="0 0 0"/>
      <geometry>
        <mesh filename="moderos_descriptions/brainco-righthand-URDF-V2/meshes/thumb_proximal_link.STL"/>
      </geometry>
      <material name="tr4_black_metal" />
    </visual>
    <collision>
      <origin rpy="0 0 0" xyz="0 0 0"/>
      <geometry>
        <mesh filename="moderos_descriptions/brainco-righthand-URDF-V2/meshes/thumb_proximal_link.STL"/>
      </geometry>
    </collision>
  </link>
  <joint name="righthand_thumb_proximal_joint" type="revolute">
    <origin rpy="0.17488 0.23736 0.16787" xyz="0 0.014227 0"/>
    <parent link="righthand_thumb_metacarpal_link"/>
    <child link="righthand_thumb_proximal_link"/>
    <axis xyz="1 0 0"/>
    <limit effort="1.1" lower="0" upper="1.0472" velocity="2.5303"/>
  </joint>
  <link name="righthand_thumb_distal_link">
    <inertial>
      <origin rpy="0 0 0" xyz="-5.88258313588552E-09 0.0117544716247142 1.13324397438969E-05"/>
      <mass value="0.00417181579838271"/>
      <inertia ixx="1.67793545309794E-07" ixy="7.15927847824152E-12" ixz="-6.80095370888918E-12" iyy="1.15362128819331E-07" iyz="1.2517499089377E-08" izz="2.19553178338424E-07"/>
    </inertial>
    <visual>
      <origin rpy="0 0 0" xyz="0 0 0"/>
      <geometry>
        <mesh filename="moderos_descriptions/brainco-righthand-URDF-V2/meshes/thumb_distal_link.STL"/>
      </geometry>
      <material name="tr4_black_metal" />
    </visual>
    <collision>
      <origin rpy="0 0 0" xyz="0 0 0"/>
      <geometry>
        <mesh filename="moderos_descriptions/brainco-righthand-URDF-V2/meshes/thumb_distal_link.STL"/>
      </geometry>
    </collision>
  </link>
  <joint name="righthand_thumb_distal_joint" type="revolute">
    <origin rpy="0 0 0" xyz="0 0.052 0"/>
    <parent link="righthand_thumb_proximal_link"/>
    <child link="righthand_thumb_distal_link"/>
    <axis xyz="1 0 0"/>
    <limit effort="1.1" lower="0" upper="1.0472" velocity="2.5303"/>
  </joint>
  <link name="righthand_thumb_tip">
    <inertial>
      <origin rpy="0 0 0" xyz="0 -8.79922039356273E-05 -1.73472347597681E-18"/>
      <mass value="6.54498469497874E-08"/>
      <inertia ixx="1.63624617374468E-15" ixy="-6.16297582203915E-33" ixz="-4.93038065763132E-32" iyy="1.63624617374468E-15" iyz="1.00148357108136E-32" izz="1.63624617374469E-15"/>
    </inertial>
    <visual>
      <origin rpy="0 0 0" xyz="0 0 0"/>
      <geometry>
        <mesh filename="moderos_descriptions/brainco-righthand-URDF-V2/meshes/thumb_tip.STL"/>
      </geometry>
      <material name="tr4_black_metal" />
    </visual>
    <collision>
      <origin rpy="0 0 0" xyz="0 0 0"/>
      <geometry>
        <mesh filename="moderos_descriptions/brainco-righthand-URDF-V2/meshes/thumb_tip.STL"/>
      </geometry>
    </collision>
  </link>
  <joint name="righthand_thumb_tip_joint" type="revolute">
    <origin rpy="-0.06675 0 0" xyz="0 0.026529 -0.0017734"/>
    <parent link="righthand_thumb_distal_link"/>
    <child link="righthand_thumb_tip"/>
    <axis xyz="1 0 0"/>
    <limit effort="0" lower="0" upper="0" velocity="0"/>
  </joint>
  <!-- === Index === -->
  <link name="righthand_index_proximal_link">
    <inertial>
      <origin rpy="0 0 0" xyz="-0.00223495193290077 3.15874279788186E-06 0.0176402020319161"/>
      <mass value="0.00195502251331252"/>
      <inertia ixx="2.51945688432676E-07" ixy="1.19772642527626E-11" ixz="-6.37275646674549E-09" iyy="2.36435336197133E-07" iyz="1.65019098402875E-10" izz="9.30351046795666E-08"/>
    </inertial>
    <visual>
      <origin rpy="0 0 0" xyz="0 0 0"/>
      <geometry>
        <mesh filename="moderos_descriptions/brainco-righthand-URDF-V2/meshes/index_proximal_link.STL"/>
      </geometry>
      <material name="tr4_black_metal" />
    </visual>
    <collision>
      <origin rpy="0 0 0" xyz="0 0 0"/>
      <geometry>
        <mesh filename="moderos_descriptions/brainco-righthand-URDF-V2/meshes/index_proximal_link.STL"/>
      </geometry>
    </collision>
  </link>
  <joint name="righthand_index_proximal_joint" type="revolute">
    <origin rpy="-0.11819 0.14743 -0.17422" xyz="-0.0021181 0.029568 0.080876"/>
    <parent link="righthand_base_link"/>
    <child link="righthand_index_proximal_link"/>
    <axis xyz="0 1 0"/>
    <limit effort="2" lower="0" upper="1.4661" velocity="2.2685"/>
  </joint>
  <link name="righthand_index_distal_link">
    <inertial>
      <origin rpy="0 0 0" xyz="0.00418341335261295 1.16596677458836E-07 0.015364336404132"/>
      <mass value="0.00406296182843578"/>
      <inertia ixx="3.65279307173044E-07" ixy="-2.87250721751561E-12" ixz="-1.02338195662283E-07" iyy="3.96973276545597E-07" iyz="-3.6418238169009E-12" izz="1.04994676979538E-07"/>
    </inertial>
    <visual>
      <origin rpy="0 0 0" xyz="0 0 0"/>
      <geometry>
        <mesh filename="moderos_descriptions/brainco-righthand-URDF-V2/meshes/index_distal_link.STL"/>
      </geometry>
      <material name="tr4_black_metal"/>
    </visual>
    <collision>
      <origin rpy="0 0 0" xyz="0 0 0"/>
      <geometry>
        <mesh filename="moderos_descriptions/brainco-righthand-URDF-V2/meshes/index_distal_link.STL"/>
      </geometry>
    </collision>
  </link>
  <joint name="righthand_index_distal_joint" type="revolute">
    <origin rpy="0 0 0" xyz="0 0 0.032"/>
    <parent link="righthand_index_proximal_link"/>
    <child link="righthand_index_distal_link"/>
    <axis xyz="0 1 0"/>
    <limit effort="2" lower="0" upper="1.693" velocity="2.2685"/>
  </joint>
  <link name="righthand_index_tip">
    <inertial>
      <origin rpy="0 0 0" xyz="0 6.93889390390723E-18 2.77555756156289E-17"/>
      <mass value="6.54498469497874E-08"/>
      <inertia ixx="1.63624617374468E-15" ixy="-4.93038065763132E-32" ixz="0" iyy="1.63624617374468E-15" iyz="-1.23259516440783E-32" izz="1.63624617374468E-15"/>
    </inertial>
    <visual>
      <origin rpy="0 0 0" xyz="0 0 0"/>
      <geometry>
        <mesh filename="moderos_descriptions/brainco-righthand-URDF-V2/meshes/index_tip.STL"/>
      </geometry>
      <material name="tr4_black_metal"/>
    </visual>
    <collision>
      <origin rpy="0 0 0" xyz="0 0 0"/>
      <geometry>
        <mesh filename="moderos_descriptions/brainco-righthand-URDF-V2/meshes/index_tip.STL"/>
      </geometry>
    </collision>
  </link>
  <joint name="righthand_index_tip_joint" type="revolute">
    <origin rpy="0 0.4756 0" xyz="0.011097 0 0.035739"/>
    <parent link="righthand_index_distal_link"/>
    <child link="righthand_index_tip"/>
    <axis xyz="0 1 0"/>
    <limit effort="0" lower="0" upper="0" velocity="0"/>
  </joint>
  <!-- === Middle === -->
  <link name="righthand_middle_proximal_link">
    <inertial>
      <origin rpy="0 0 0" xyz="-0.00222511101223748 5.25632286621502E-06 0.0203007776295122"/>
      <mass value="0.00232228766449838"/>
      <inertia ixx="3.66996237195385E-07" ixy="2.68340899394266E-11" ixz="-9.79836587937118E-09" iyy="3.52645347928617E-07" iyz="2.57865582739015E-10" izz="1.12233932527467E-07"/>
    </inertial>
    <visual>
      <origin rpy="0 0 0" xyz="0 0 0"/>
      <geometry>
        <mesh filename="moderos_descriptions/brainco-righthand-URDF-V2/meshes/middle_proximal_link.STL"/>
      </geometry>
      <material name="tr4_black_metal"/>
    </visual>
    <collision>
      <origin rpy="0 0 0" xyz="0 0 0"/>
      <geometry>
        <mesh filename="moderos_descriptions/brainco-righthand-URDF-V2/meshes/middle_proximal_link.STL"/>
      </geometry>
    </collision>
  </link>
  <joint name="righthand_middle_proximal_joint" type="revolute">
    <origin rpy="-0.039468 0.1483 -0.057975" xyz="-0.0045767 0.010051 0.084993"/>
    <parent link="righthand_base_link"/>
    <child link="righthand_middle_proximal_link"/>
    <axis xyz="0 1 0"/>
    <limit effort="2" lower="0" upper="1.4661" velocity="2.2685"/>
  </joint>
  <link name="righthand_middle_distal_link">
    <inertial>
      <origin rpy="0 0 0" xyz="0.0049863469326964 3.20968126441695E-07 0.0178210318376746"/>
      <mass value="0.00491866388593896"/>
      <inertia ixx="5.54531291618193E-07" ixy="-3.82751343578468E-12" ixz="-1.61139292206417E-07" iyy="6.07133263023386E-07" iyz="-1.20501452509702E-11" izz="1.45091109192225E-07"/>
    </inertial>
    <visual>
      <origin rpy="0 0 0" xyz="0 0 0"/>
      <geometry>
        <mesh filename="moderos_descriptions/brainco-righthand-URDF-V2/meshes/middle_distal_link.STL"/>
      </geometry>
      <material name="tr4_black_metal"/>
    </visual>
    <collision>
      <origin rpy="0 0 0" xyz="0 0 0"/>
      <geometry>
        <mesh filename="moderos_descriptions/brainco-righthand-URDF-V2/meshes/middle_distal_link.STL"/>
      </geometry>
    </collision>
  </link>
  <joint name="righthand_middle_distal_joint" type="revolute">
    <origin rpy="0 0 0" xyz="0 0 0.037"/>
    <parent link="righthand_middle_proximal_link"/>
    <child link="righthand_middle_distal_link"/>
    <axis xyz="0 1 0"/>
    <limit effort="2" lower="0" upper="1.693" velocity="2.2685"/>
  </joint>
  <link name="righthand_middle_tip">
    <inertial>
      <origin rpy="0 0 0" xyz="0 -3.46944695195361E-18 0"/>
      <mass value="6.54498469497874E-08"/>
      <inertia ixx="1.63624617374468E-15" ixy="-6.16297582203915E-33" ixz="9.86076131526265E-32" iyy="1.63624617374468E-15" iyz="3.08148791101958E-33" izz="1.63624617374468E-15"/>
    </inertial>
    <visual>
      <origin rpy="0 0 0" xyz="0 0 0"/>
      <geometry>
        <mesh filename="moderos_descriptions/brainco-righthand-URDF-V2/meshes/middle_tip.STL"/>
      </geometry>
      <material name="tr4_black_metal"/>
    </visual>
    <collision>
      <origin rpy="0 0 0" xyz="0 0 0"/>
      <geometry>
        <mesh filename="moderos_descriptions/brainco-righthand-URDF-V2/meshes/middle_tip.STL"/>
      </geometry>
    </collision>
  </link>
  <joint name="righthand_middle_tip_joint" type="revolute">
    <origin rpy="0 0.475602221168456 0" xyz="0.0125575670114349 0 0.0404419749600572"/>
    <parent link="righthand_middle_distal_link"/>
    <child link="righthand_middle_tip"/>
    <axis xyz="0 -1 0"/>
    <limit effort="0" lower="0" upper="0" velocity="0"/>
  </joint>
  <!-- === Ring === -->
  <link name="righthand_ring_proximal_link">
    <inertial>
      <origin rpy="0 0 0" xyz="-0.00234494526421466 5.8795475560789E-06 0.0191774025495976"/>
      <mass value="0.00214992998311425"/>
      <inertia ixx="3.14177684848331E-07" ixy="3.3438233110566E-11" ixz="-7.7898178089235E-09" iyy="2.97613170150892E-07" iyz="2.41251871798122E-10" izz="1.02115432336749E-07"/>
    </inertial>
    <visual>
      <origin rpy="0 0 0" xyz="0 0 0"/>
      <geometry>
        <mesh filename="moderos_descriptions/brainco-righthand-URDF-V2/meshes/ring_proximal_link.STL"/>
      </geometry>
      <material name="tr4_black_metal"/>
    </visual>
    <collision>
      <origin rpy="0 0 0" xyz="0 0 0"/>
      <geometry>
        <mesh filename="moderos_descriptions/brainco-righthand-URDF-V2/meshes/ring_proximal_link.STL"/>
      </geometry>
    </collision>
  </link>
  <joint name="righthand_ring_proximal_joint" type="revolute">
    <origin rpy="0.039462 0.14721 0.057932" xyz="-0.0046709 -0.010037 0.083982"/>
    <parent link="righthand_base_link"/>
    <child link="righthand_ring_proximal_link"/>
    <axis xyz="0 1 0"/>
    <limit effort="2" lower="0" upper="1.4661" velocity="2.2685"/>
  </joint>
  <link name="righthand_ring_distal_link">
    <inertial>
      <origin rpy="0 0 0" xyz="0.00471282047041737 -2.42853075739513E-08 0.0172486573668856"/>
      <mass value="0.00466283373690043"/>
      <inertia ixx="5.09075629611805E-07" ixy="-3.12030946891553E-12" ixz="-1.48822357561025E-07" iyy="5.56818055205826E-07" iyz="-3.81917701976479E-12" izz="1.34389193498435E-07"/>
    </inertial>
    <visual>
      <origin rpy="0 0 0" xyz="0 0 0"/>
      <geometry>
        <mesh filename="moderos_descriptions/brainco-righthand-URDF-V2/meshes/ring_distal_link.STL"/>
      </geometry>
      <material name="tr4_black_metal"/>
    </visual>
    <collision>
      <origin rpy="0 0 0" xyz="0 0 0"/>
      <geometry>
        <mesh filename="moderos_descriptions/brainco-righthand-URDF-V2/meshes/ring_distal_link.STL"/>
      </geometry>
    </collision>
  </link>
  <joint name="righthand_ring_distal_joint" type="revolute">
    <origin rpy="0 0 0" xyz="0 0 0.035"/>
    <parent link="righthand_ring_proximal_link"/>
    <child link="righthand_ring_distal_link"/>
    <axis xyz="0 1 0"/>
    <limit effort="2" lower="0" upper="1.693" velocity="2.2685"/>
  </joint>
  <link name="righthand_ring_tip">
    <inertial>
      <origin rpy="0 0 0" xyz="0 0 0"/>
      <mass value="6.54498469497874E-08"/>
      <inertia ixx="1.63624617374468E-15" ixy="-6.16297582203915E-33" ixz="9.86076131526265E-32" iyy="1.63624617374468E-15" iyz="0" izz="1.63624617374468E-15"/>
    </inertial>
    <visual>
      <origin rpy="0 0 0" xyz="0 0 0"/>
      <geometry>
        <mesh filename="moderos_descriptions/brainco-righthand-URDF-V2/meshes/ring_tip.STL"/>
      </geometry>
      <material name="tr4_black_metal"/>
    </visual>
    <collision>
      <origin rpy="0 0 0" xyz="0 0 0"/>
      <geometry>
        <mesh filename="moderos_descriptions/brainco-righthand-URDF-V2/meshes/ring_tip.STL"/>
      </geometry>
    </collision>
  </link>
  <joint name="righthand_ring_tip_joint" type="revolute">
    <origin rpy="0 0.4756 0" xyz="0.012266 0 0.039501"/>
    <parent link="righthand_ring_distal_link"/>
    <child link="righthand_ring_tip"/>
    <axis xyz="0 1 0"/>
    <limit effort="0" lower="0" upper="0" velocity="0"/>
  </joint>
  <!-- === Pinky === -->
  <link name="righthand_pinky_proximal_link">
    <inertial>
      <origin rpy="0 0 0" xyz="-0.00213212021184184 7.75039446080511E-06 0.0160671583560377"/>
      <mass value="0.00173854673404671"/>
      <inertia ixx="1.975632135501E-07" ixy="2.23402433053397E-11" ixz="-4.58425663692231E-09" iyy="1.8202304308332E-07" iyz="1.08028441148425E-10" izz="8.21624712033188E-08"/>
    </inertial>
    <visual>
      <origin rpy="0 0 0" xyz="0 0 0"/>
      <geometry>
        <mesh filename="moderos_descriptions/brainco-righthand-URDF-V2/meshes/pinky_proximal_link.STL"/>
      </geometry>
      <material name="tr4_black_metal"/>
    </visual>
    <collision>
      <origin rpy="0 0 0" xyz="0 0 0"/>
      <geometry>
        <mesh filename="moderos_descriptions/brainco-righthand-URDF-V2/meshes/pinky_proximal_link.STL"/>
      </geometry>
    </collision>
  </link>
  <joint name="righthand_pinky_proximal_joint" type="revolute">
    <origin rpy="0.11815 0.14491 0.17392" xyz="-0.0023566 -0.029366 0.078694"/>
    <parent link="righthand_base_link"/>
    <child link="righthand_pinky_proximal_link"/>
    <axis xyz="0 1 0"/>
    <limit effort="2" lower="0" upper="1.466076572" velocity="2.2685"/>
  </joint>
  <link name="righthand_pinky_distal_link">
    <inertial>
      <origin rpy="0 0 0" xyz="0.00398575710171677 -1.18612275255142E-07 0.014107352014143"/>
      <mass value="0.00375757190949148"/>
      <inertia ixx="2.8828728315904E-07" ixy="8.06578660095813E-13" ixz="-7.78224737732238E-08" iyy="3.10873475225446E-07" iyz="3.24944213201207E-12" izz="9.12935515594715E-08"/>
    </inertial>
    <visual>
      <origin rpy="0 0 0" xyz="0 0 0"/>
      <geometry>
        <mesh filename="moderos_descriptions/brainco-righthand-URDF-V2/meshes/pinky_distal_link.STL"/>
      </geometry>
      <material name="tr4_black_metal"/>
    </visual>
    <collision>
      <origin rpy="0 0 0" xyz="0 0 0"/>
      <geometry>
        <mesh filename="moderos_descriptions/brainco-righthand-URDF-V2/meshes/pinky_distal_link.STL"/>
      </geometry>
    </collision>
  </link>
  <joint name="righthand_pinky_distal_joint" type="revolute">
    <origin rpy="0 0 0" xyz="0 0 0.029"/>
    <parent link="righthand_pinky_proximal_link"/>
    <child link="righthand_pinky_distal_link"/>
    <axis xyz="0 1 0"/>
    <limit effort="2" lower="0" upper="1.693" velocity="2.2685"/>
  </joint>
  <link name="righthand_pinky_tip">
    <inertial>
      <origin rpy="0 0 0" xyz="3.46944695195361E-18 -5.20417042793042E-18 0"/>
      <mass value="6.54498469497874E-08"/>
      <inertia ixx="1.63624617374468E-15" ixy="0" ixz="0" iyy="1.63624617374468E-15" iyz="4.93038065763132E-32" izz="1.63624617374468E-15"/>
    </inertial>
    <visual>
      <origin rpy="0 0 0" xyz="0 0 0"/>
      <geometry>
        <mesh filename="moderos_descriptions/brainco-righthand-URDF-V2/meshes/pinky_tip.STL"/>
      </geometry>
      <material name="tr4_black_metal"/>
    </visual>
    <collision>
      <origin rpy="0 0 0" xyz="0 0 0"/>
      <geometry>
        <mesh filename="moderos_descriptions/brainco-righthand-URDF-V2/meshes/pinky_tip.STL"/>
      </geometry>
    </collision>
  </link>
  <joint name="righthand_pinky_tip_joint" type="revolute">
    <origin rpy="0 0.4756 0" xyz="0.010221 0 0.032918"/>
    <parent link="righthand_pinky_distal_link"/>
    <child link="righthand_pinky_tip"/>
    <axis xyz="0 1 0"/>
    <limit effort="0" lower="0" upper="0" velocity="0"/>
  </joint>
</robot>
